Traceback (most recent call last):
  File "/home/valmseb/.local/lib/python3.8/site-packages/pandas/core/indexes/base.py", line 3621, in get_loc
    return self._engine.get_loc(casted_key)
  File "pandas/_libs/index.pyx", line 136, in pandas._libs.index.IndexEngine.get_loc
  File "pandas/_libs/index.pyx", line 163, in pandas._libs.index.IndexEngine.get_loc
  File "pandas/_libs/hashtable_class_helper.pxi", line 5198, in pandas._libs.hashtable.PyObjectHashTable.get_item
  File "pandas/_libs/hashtable_class_helper.pxi", line 5206, in pandas._libs.hashtable.PyObjectHashTable.get_item
KeyError: 'IKr block'

The above exception was the direct cause of the following exception:

Traceback (most recent call last):
  File "compute_score.py", line 84, in <module>
    print('Computing condition ' + str(i) + '. IKr rescale : ' + str(1-0.01*float(dataset_pharm['IKr block'][i])) + ', ICaL rescale: ' + str(1-0.01*float(dataset_pharm['ICaL block'][i])))
  File "/home/valmseb/.local/lib/python3.8/site-packages/pandas/core/frame.py", line 3505, in __getitem__
    indexer = self.columns.get_loc(key)
  File "/home/valmseb/.local/lib/python3.8/site-packages/pandas/core/indexes/base.py", line 3623, in get_loc
    raise KeyError(key) from err
KeyError: 'IKr block'
